Workbook
Name A_Limit: Inputs!$C$19
Name B_Limit: Inputs!$C$20
Name BestClass: Backtest!$H$5:$H$13
Name BestFlat: Backtest!$W$5:$W$13
Name BestMethod: Backtest!$V$5:$V$13
Name BtAbsErr: Backtest!$D$5:$D$604
Name BtActual: Backtest!$C$5:$C$604
Name BtClass: Backtest!$F$5:$F$604
Name BtCode: Backtest!$A$5:$A$604
Name BtErr: Backtest!$E$5:$E$604
Name BtMethod: Backtest!$B$5:$B$604
Name ClassList: Inputs!$B$29:$B$31
Name ClassSL: Inputs!$C$29:$C$31
Name ClsABC: ABC_XYZ!$F$5:$F$154
Name ClsClass: ABC_XYZ!$K$5:$K$154
Name ClsCode: ABC_XYZ!$A$5:$A$154
Name ClsSeasonal: ABC_XYZ!$M$5:$M$154
Name ClsValue: ABC_XYZ!$C$5:$C$154
Name ClsXYZ: ABC_XYZ!$J$5:$J$154
Name CostRatio: Inputs!$C$15
Name CurrentCover: Inputs!$C$16
Name DemandAll: Demand!$C$5:$DA$154
Name DemandCodes: Demand!$A$5:$A$154
Name DemandLast52: Demand!$BB$5:$DA$154
Name DemandPeak2010: Demand!$AP$5:$BB$154
Name DemandTrain: Demand!$C$5:$CO$154
Name FutCode: Forecast_Future!$A$5:$A$7204
Name FutHorizon: Forecast_Future!$C$5:$C$7204
Name FutMethod: Forecast_Future!$B$5:$B$7204
Name FutUnits: Forecast_Future!$E$5:$E$7204
Name HoldingRate: Inputs!$C$13
Name LeadTime: Inputs!$C$12
Name OrderCost: Inputs!$C$14
Name ParamCodes: Model_Params!$A$5:$A$154
Name PolClass: Policy!$C$5:$C$154
Name PolCode: Policy!$A$5:$A$154
Name PolCost: Policy!$G$5:$G$154
Name PolCur: Policy!$T$5:$T$154
Name PolFreed: Policy!$V$5:$V$154
Name PolHold: Policy!$Z$5:$Z$154
Name PolMethod: Policy!$D$5:$D$154
Name PolOrdCost: Policy!$AA$5:$AA$154
Name PolOrder: Policy!$Y$5:$Y$154
Name PolRank: Policy!$AC$5:$AC$154
Name PolRec: Policy!$U$5:$U$154
Name PolRisk: Policy!$X$5:$X$154
Name PolSD: Policy!$F$5:$F$154
Name PolShort: Policy!$AB$5:$AB$154
Name PolSS: Policy!$K$5:$K$154
Name PolStatus: Policy!$W$5:$W$154
Name SeasonalLimit: Inputs!$C$25
Name ServiceLevel: Inputs!$C$5
Name SKUList: SKU_Data!$A$5:$A$154
Name SL_A: Inputs!$C$8
Name SL_B: Inputs!$C$9
Name SL_C: Inputs!$C$10
Name WeeksPerYear: Inputs!$C$17
Name X_Limit: Inputs!$C$22
Name Y_Limit: Inputs!$C$23
Name Z: Inputs!$C$6

Sheet Start
A1: Inventory Planning & Demand Forecasting Model
A2: UK online gift retailer (UCI Online Retail II, real data) · 150 top SKUs · 103 weeks Dec-2009 to Nov-2011 · built for learning
B4: What it answers | C4: How much stock should we hold for each product, and when should we reorder, so we don't run out or overstock?
B5: How to use it | C5: 1) Change the yellow cells on the Inputs sheet (service level, lead time, costs). Every sheet recalculates. 2) Pick a product in the drop-down on the Forecast sheet to see its four forecasts and their accuracy. 3) Read the results on Summary and Charts; the full SKU list with reorder points is on Policy.
B6: Colour code | C6: Yellow cell, blue text = an input you can change. Grey cells = data from the CSVs (don't type over). Everything else = a formula. Click any cell and read the formula bar.
B8: SHEETS
B9: Inputs | C9: All assumptions in one place: service level (and z), lead time, holding and ordering cost, unit cost, current stock, class limits.
B10: ABC_XYZ | C10: ABC by value (cumulative share, SUMIFS), XYZ by demand variability (CV = STDEV.S / AVERAGE), the 9-box matrix (COUNTIFS).
B11: Forecast | C11: One SKU at a time (drop-down): naive, moving average, simple exponential smoothing and Holt-Winters written out week by week, plus Excel's own FORECAST.ETS. 12-week backtest with WAPE, MAPE and bias.
B12: Backtest | C12: Errors of all four methods for all 150 SKUs (from notebook 02), summed by ABC-XYZ class with SUMIFS. Picks the best method per class.
B13: Policy | C13: Every SKU: safety stock, reorder point, EOQ, min/max, weeks of cover, current vs recommended stock, stock-out risk, order suggestion.
B14: Summary | C14: Headline numbers, results by class, the service level vs cost trade-off and the top-10 reorder list.
B15: Charts | C15: Forecast vs actual for the selected SKU, stock by class, the trade-off curve, the 9-box and the Pareto curve.
B16: Demand, SKU_Data, Model_Params, Forecast_Future | C16: Data sheets (grey): weekly demand, SKU facts, fitted smoothing parameters, future forecasts.
B18: KEY FORMULAS
B19: Safety stock | C19: Safety stock = z × σ(weekly demand) × √(lead time in weeks), z = NORM.S.INV(service level)
B20: Reorder point (Min) | C20: ROP = forecast demand during the lead time + safety stock
B21: EOQ | C21: EOQ = √(2 × annual demand × ordering cost ÷ (holding cost % × unit cost))
B22: Max | C22: Max = reorder point + EOQ. Average stock = safety stock + EOQ ÷ 2. Weeks of cover = stock ÷ average weekly demand
B24: ASSUMPTIONS | C24: The data has no lead times, costs or stock levels, so these are assumptions (see Inputs and the README): lead time 3 weeks, holding cost 25% a year, £50 per order, unit cost 60% of selling price, current stock = 8 weeks of average demand.

Sheet Inputs
A1: Inputs (change the yellow cells)
A2: Everything in the model reads from this sheet. Named ranges in column E make the formulas readable.
B4: Assumption | C4: Value | D4: What it means / why this value | E4: Name in formulas
B5: Target service level | C5: 0.95 | D5: Chance of NOT running out during a lead time. 95% is the brief's default. | E5: ServiceLevel
B6: z (safety factor) | C6: =_xlfn.NORM.S.INV(C5) -> 1.6448536 | D6: z = NORM.S.INV(service level). 95% gives 1.645. | E6: Z
B8: Service level for A items (optional) | D8: Leave blank to use the target above. Try 98% for A, 90% for C. | E8: SL_A
B9: Service level for B items (optional) | E9: SL_B
B10: Service level for C items (optional) | E10: SL_C
B12: Lead time (weeks) | C12: 3 | D12: Order to delivery. Brief range 2-4 weeks; most stock is imported. | E12: LeadTime
B13: Holding cost (% of unit cost per year) | C13: 0.25 | D13: Storage, capital, insurance, damage, obsolescence. Brief range 20-25%. | E13: HoldingRate
B14: Ordering cost (£ per order) | C14: 50 | D14: Admin, freight booking and receiving for one purchase order line. | E14: OrderCost
B15: Unit cost (% of selling price) | C15: 0.6 | D15: The data only has selling prices; 60% = a 40% gross margin. | E15: CostRatio
B16: Current stock (weeks of average demand) | C16: 8 | D16: No stock data, so assume today's blanket rule: 8 weeks of cover for every SKU. | E16: CurrentCover
B17: Weeks per year | C17: 52 | E17: WeeksPerYear
B19: ABC: A = first ...% of value | C19: 0.8 | D19: Cumulative share of sales value. Classic split 80 / 15 / 5. | E19: A_Limit
B20: ABC: B = up to ...% of value | C20: 0.95 | D20: The rest is C. | E20: B_Limit
B22: XYZ: X = CV up to | C22: 0.75 | D22: CV = std dev / average of weekly demand. Weekly data is noisy, so the limits are higher than the monthly 0.5 / 1.0. | E22: X_Limit
B23: XYZ: Y = CV up to | C23: 1.25 | D23: Above this = Z (erratic). | E23: Y_Limit
B25: Seasonal if Christmas uplift at least | C25: 1.3 | D25: Uplift = avg demand Sep-Nov 2010 / avg over the training weeks. Seasonal SKUs may use Holt-Winters. | E25: SeasonalLimit
B27: Class service levels (used by the Policy sheet: blank override = target service level)
B28: Class | C28: Service level used | D28: z used
B29: A | C29: =IF(SL_A="",ServiceLevel,SL_A) -> 0.95 | D29: =_xlfn.NORM.S.INV(C29) -> 1.6448536
B30: B | C30: =IF(SL_B="",ServiceLevel,SL_B) -> 0.95 | D30: =_xlfn.NORM.S.INV(C30) -> 1.6448536
B31: C | C31: =IF(SL_C="",ServiceLevel,SL_C) -> 0.95 | D31: =_xlfn.NORM.S.INV(C31) -> 1.6448536

Sheet Summary
A1: Summary: current vs recommended stock
A2: All numbers update when you change Inputs. £ values are at cost (unit cost = selling price × unit cost %).
B4: Current stock value | C4: Recommended avg stock | D4: Working capital freed | E4: Stock reduction | F4: SKUs to reorder now | G4: SKUs overstocked
B5: =SUM(PolCur) -> 294811.67 | C5: =SUM(PolRec) -> 270948.37 | D5: =SUM(PolFreed) -> 23863.307 | E5: =1-SUM(PolRec)/SUM(PolCur) -> 0.080944242 | F5: =COUNTIF(PolStatus,"Reorder now") -> 29 | G5: =COUNTIF(PolStatus,"Overstock") -> 1
B6: ="Service level "&TEXT(ServiceLevel,"0.0%")&" · lead time "&LeadTime&" wks · holding "&TEXT(HoldingRate,"0%")&" · £"&OrderCost&" per order · current stock = "&CurrentCover&" weeks of cover" -> Service level 95.0% · lead time 3 wks · holding 25% · £50 per order · current stock = 8 weeks of cover
B8: By ABC class | I8: Service level vs cost trade-off (all SKUs at the same service level)
B9: Class | C9: SKUs | D9: Current stock (£) | E9: Recommended (£) | F9: Freed (£) | G9: Reorder now | I9: Service level | J9: z | K9: Safety stock (£) | L9: Holding cost / yr (£) | M9: Extra £ vs row above
B10: A | C10: =COUNTIF(PolClass,"A*") -> 95 | D10: =SUMIFS(PolCur,PolClass,"A*") -> 235312.33 | E10: =SUMIFS(PolRec,PolClass,"A*") -> 200217.84 | F10: =D10-E10 -> 35094.491 | G10: =COUNTIFS(PolClass,"A*",PolStatus,"Reorder now") -> 19 | I10: 0.8 | J10: =_xlfn.NORM.S.INV(I10) -> 0.84162123 | K10: =J10*SUMPRODUCT(PolSD,PolCost)*SQRT(LeadTime) -> 55552.178 | L10: =K10*HoldingRate -> 13888.044
B11: B | C11: =COUNTIF(PolClass,"B*") -> 39 | D11: =SUMIFS(PolCur,PolClass,"B*") -> 44000.566 | E11: =SUMIFS(PolRec,PolClass,"B*") -> 52183.196 | F11: =D11-E11 -> -8182.6295 | G11: =COUNTIFS(PolClass,"B*",PolStatus,"Reorder now") -> 6 | I11: 0.85 | J11: =_xlfn.NORM.S.INV(I11) -> 1.0364334 | K11: =J11*SUMPRODUCT(PolSD,PolCost)*SQRT(LeadTime) -> 68410.978 | L11: =K11*HoldingRate -> 17102.745 | M11: =K11-K10 -> 12858.801
B12: C | C12: =COUNTIF(PolClass,"C*") -> 16 | D12: =SUMIFS(PolCur,PolClass,"C*") -> 15498.772 | E12: =SUMIFS(PolRec,PolClass,"C*") -> 18547.326 | F12: =D12-E12 -> -3048.5543 | G12: =COUNTIFS(PolClass,"C*",PolStatus,"Reorder now") -> 4 | I12: 0.9 | J12: =_xlfn.NORM.S.INV(I12) -> 1.2815516 | K12: =J12*SUMPRODUCT(PolSD,PolCost)*SQRT(LeadTime) -> 84590.286 | L12: =K12*HoldingRate -> 21147.571 | M12: =K12-K11 -> 16179.307
B13: Total | C13: =SUM(C10:C12) -> 150 | D13: =SUM(D10:D12) -> 294811.67 | E13: =SUM(E10:E12) -> 270948.37 | F13: =SUM(F10:F12) -> 23863.307 | G13: =SUM(G10:G12) -> 29 | I13: 0.925 | J13: =_xlfn.NORM.S.INV(I13) -> 1.4395315 | K13: =J13*SUMPRODUCT(PolSD,PolCost)*SQRT(LeadTime) -> 95017.931 | L13: =K13*HoldingRate -> 23754.483 | M13: =K13-K12 -> 10427.645
I14: 0.95 | J14: =_xlfn.NORM.S.INV(I14) -> 1.6448536 | K14: =J14*SUMPRODUCT(PolSD,PolCost)*SQRT(LeadTime) -> 108570.46 | L14: =K14*HoldingRate -> 27142.614 | M14: =K14-K13 -> 13552.525
B15: By XYZ class (the blanket rule over-stocks steady items and under-stocks erratic ones) | I15: 0.97 | J15: =_xlfn.NORM.S.INV(I15) -> 1.8807936 | K15: =J15*SUMPRODUCT(PolSD,PolCost)*SQRT(LeadTime) -> 124143.95 | L15: =K15*HoldingRate -> 31035.987 | M15: =K15-K14 -> 15573.49
B16: Class | C16: SKUs | D16: Current stock (£) | E16: Recommended (£) | F16: Freed (£) | G16: Reorder now | I16: 0.98 | J16: =_xlfn.NORM.S.INV(I16) -> 2.0537489 | K16: =J16*SUMPRODUCT(PolSD,PolCost)*SQRT(LeadTime) -> 135560.06 | L16: =K16*HoldingRate -> 33890.015 | M16: =K16-K15 -> 11416.114
B17: X | C17: =COUNTIF(PolClass,"?X") -> 51 | D17: =SUMIFS(PolCur,PolClass,"?X") -> 115835.34 | E17: =SUMIFS(PolRec,PolClass,"?X") -> 83627.462 | F17: =D17-E17 -> 32207.882 | G17: =COUNTIFS(PolClass,"?X",PolStatus,"Reorder now") -> 0 | I17: 0.99 | J17: =_xlfn.NORM.S.INV(I17) -> 2.3263479 | K17: =J17*SUMPRODUCT(PolSD,PolCost)*SQRT(LeadTime) -> 153553.27 | L17: =K17*HoldingRate -> 38388.317 | M17: =K17-K16 -> 17993.208
B18: Y | C18: =COUNTIF(PolClass,"?Y") -> 55 | D18: =SUMIFS(PolCur,PolClass,"?Y") -> 100151.81 | E18: =SUMIFS(PolRec,PolClass,"?Y") -> 92204.566 | F18: =D18-E18 -> 7947.2443 | G18: =COUNTIFS(PolClass,"?Y",PolStatus,"Reorder now") -> 3 | I18: 0.995 | J18: =_xlfn.NORM.S.INV(I18) -> 2.5758293 | K18: =J18*SUMPRODUCT(PolSD,PolCost)*SQRT(LeadTime) -> 170020.58 | L18: =K18*HoldingRate -> 42505.144 | M18: =K18-K17 -> 16467.309
B19: Z | C19: =COUNTIF(PolClass,"?Z") -> 44 | D19: =SUMIFS(PolCur,PolClass,"?Z") -> 78824.519 | E19: =SUMIFS(PolRec,PolClass,"?Z") -> 95116.338 | F19: =D19-E19 -> -16291.819 | G19: =COUNTIFS(PolClass,"?Z",PolStatus,"Reorder now") -> 26 | I19: Going from 95% to 99% needs about 40% more safety stock: each extra point of service costs more than the last.
B22: Yearly running cost of the recommended policy | I22: Top 10 SKUs to reorder now (biggest shortfall below the reorder point, LARGE + INDEX/MATCH)
B23: Holding cost / year | C23: =SUM(PolHold) -> 67737.091 | D23: EOQ is where these two are equal: order more often → less stock but more orders. | I23: Stock code | J23: Class | K23: Shortfall (£) | L23: Order qty | M23: Stock-out risk
B24: Ordering cost / year | C24: =SUM(PolOrdCost) -> 40501.295 | I24: =IF(INDEX(PolShort,MATCH(LARGE(PolRank,1),PolRank,0))=0,"",INDEX(PolCode,MATCH(LARGE(PolRank,1),PolRank,0))) -> 22086 | J24: =IF(I24="","",INDEX(PolClass,MATCH(LARGE(PolRank,1),PolRank,0))) -> AZ | K24: =IF(I24="","",INDEX(PolShort,MATCH(LARGE(PolRank,1),PolRank,0))) -> 1761.7022 | L24: =IF(I24="","",INDEX(PolOrder,MATCH(LARGE(PolRank,1),PolRank,0))) -> 2654 | M24: =IF(I24="","",INDEX(PolRisk,MATCH(LARGE(PolRank,1),PolRank,0))) -> 0.24469079
B25: Total | C25: =C23+C24 -> 108238.39 | I25: =IF(INDEX(PolShort,MATCH(LARGE(PolRank,2),PolRank,0))=0,"",INDEX(PolCode,MATCH(LARGE(PolRank,2),PolRank,0))) -> 22114 | J25: =IF(I25="","",INDEX(PolClass,MATCH(LARGE(PolRank,2),PolRank,0))) -> AZ | K25: =IF(I25="","",INDEX(PolShort,MATCH(LARGE(PolRank,2),PolRank,0))) -> 1700.6145 | L25: =IF(I25="","",INDEX(PolOrder,MATCH(LARGE(PolRank,2),PolRank,0))) -> 1254 | M25: =IF(I25="","",INDEX(PolRisk,MATCH(LARGE(PolRank,2),PolRank,0))) -> 0.54923587
B26: Safety stock value | C26: =SUMPRODUCT(PolSS,PolCost) -> 108772.68 | I26: =IF(INDEX(PolShort,MATCH(LARGE(PolRank,3),PolRank,0))=0,"",INDEX(PolCode,MATCH(LARGE(PolRank,3),PolRank,0))) -> 15056BL | J26: =IF(I26="","",INDEX(PolClass,MATCH(LARGE(PolRank,3),PolRank,0))) -> AY | K26: =IF(I26="","",INDEX(PolShort,MATCH(LARGE(PolRank,3),PolRank,0))) -> 1429.5387 | L26: =IF(I26="","",INDEX(PolOrder,MATCH(LARGE(PolRank,3),PolRank,0))) -> 992 | M26: =IF(I26="","",INDEX(PolRisk,MATCH(LARGE(PolRank,3),PolRank,0))) -> 0.99894985
I27: =IF(INDEX(PolShort,MATCH(LARGE(PolRank,4),PolRank,0))=0,"",INDEX(PolCode,MATCH(LARGE(PolRank,4),PolRank,0))) -> 22111 | J27: =IF(I27="","",INDEX(PolClass,MATCH(LARGE(PolRank,4),PolRank,0))) -> AZ | K27: =IF(I27="","",INDEX(PolShort,MATCH(LARGE(PolRank,4),PolRank,0))) -> 1342.3407 | L27: =IF(I27="","",INDEX(PolOrder,MATCH(LARGE(PolRank,4),PolRank,0))) -> 1170 | M27: =IF(I27="","",INDEX(PolRisk,MATCH(LARGE(PolRank,4),PolRank,0))) -> 0.58023227
I28: =IF(INDEX(PolShort,MATCH(LARGE(PolRank,5),PolRank,0))=0,"",INDEX(PolCode,MATCH(LARGE(PolRank,5),PolRank,0))) -> 84029E | J28: =IF(I28="","",INDEX(PolClass,MATCH(LARGE(PolRank,5),PolRank,0))) -> AZ | K28: =IF(I28="","",INDEX(PolShort,MATCH(LARGE(PolRank,5),PolRank,0))) -> 933.91955 | L28: =IF(I28="","",INDEX(PolOrder,MATCH(LARGE(PolRank,5),PolRank,0))) -> 1144 | M28: =IF(I28="","",INDEX(PolRisk,MATCH(LARGE(PolRank,5),PolRank,0))) -> 0.25244502
I29: =IF(INDEX(PolShort,MATCH(LARGE(PolRank,6),PolRank,0))=0,"",INDEX(PolCode,MATCH(LARGE(PolRank,6),PolRank,0))) -> 21623 | J29: =IF(I29="","",INDEX(PolClass,MATCH(LARGE(PolRank,6),PolRank,0))) -> AZ | K29: =IF(I29="","",INDEX(PolShort,MATCH(LARGE(PolRank,6),PolRank,0))) -> 915.87684 | L29: =IF(I29="","",INDEX(PolOrder,MATCH(LARGE(PolRank,6),PolRank,0))) -> 772 | M29: =IF(I29="","",INDEX(PolRisk,MATCH(LARGE(PolRank,6),PolRank,0))) -> 0.15438969
I30: =IF(INDEX(PolShort,MATCH(LARGE(PolRank,7),PolRank,0))=0,"",INDEX(PolCode,MATCH(LARGE(PolRank,7),PolRank,0))) -> 84029G | J30: =IF(I30="","",INDEX(PolClass,MATCH(LARGE(PolRank,7),PolRank,0))) -> AZ | K30: =IF(I30="","",INDEX(PolShort,MATCH(LARGE(PolRank,7),PolRank,0))) -> 899.32348 | L30: =IF(I30="","",INDEX(PolOrder,MATCH(LARGE(PolRank,7),PolRank,0))) -> 995 | M30: =IF(I30="","",INDEX(PolRisk,MATCH(LARGE(PolRank,7),PolRank,0))) -> 0.49711742
I31: =IF(INDEX(PolShort,MATCH(LARGE(PolRank,8),PolRank,0))=0,"",INDEX(PolCode,MATCH(LARGE(PolRank,8),PolRank,0))) -> 21108 | J31: =IF(I31="","",INDEX(PolClass,MATCH(LARGE(PolRank,8),PolRank,0))) -> BZ | K31: =IF(I31="","",INDEX(PolShort,MATCH(LARGE(PolRank,8),PolRank,0))) -> 794.0542 | L31: =IF(I31="","",INDEX(PolOrder,MATCH(LARGE(PolRank,8),PolRank,0))) -> 2321 | M31: =IF(I31="","",INDEX(PolRisk,MATCH(LARGE(PolRank,8),PolRank,0))) -> 0.23724157
I32: =IF(INDEX(PolShort,MATCH(LARGE(PolRank,9),PolRank,0))=0,"",INDEX(PolCode,MATCH(LARGE(PolRank,9),PolRank,0))) -> 22087 | J32: =IF(I32="","",INDEX(PolClass,MATCH(LARGE(PolRank,9),PolRank,0))) -> BZ | K32: =IF(I32="","",INDEX(PolShort,MATCH(LARGE(PolRank,9),PolRank,0))) -> 750.99486 | L32: =IF(I32="","",INDEX(PolOrder,MATCH(LARGE(PolRank,9),PolRank,0))) -> 1396 | M32: =IF(I32="","",INDEX(PolRisk,MATCH(LARGE(PolRank,9),PolRank,0))) -> 0.66880863
I33: =IF(INDEX(PolShort,MATCH(LARGE(PolRank,10),PolRank,0))=0,"",INDEX(PolCode,MATCH(LARGE(PolRank,10),PolRank,0))) -> 21485 | J33: =IF(I33="","",INDEX(PolClass,MATCH(LARGE(PolRank,10),PolRank,0))) -> AZ | K33: =IF(I33="","",INDEX(PolShort,MATCH(LARGE(PolRank,10),PolRank,0))) -> 750.20475 | L33: =IF(I33="","",INDEX(PolOrder,MATCH(LARGE(PolRank,10),PolRank,0))) -> 921 | M33: =IF(I33="","",INDEX(PolRisk,MATCH(LARGE(PolRank,10),PolRank,0))) -> 0.43060572

Sheet Charts
A1: Charts
A2: All charts read live from the model sheets. The first one follows the SKU picked on the Forecast sheet.

Sheet ABC_XYZ
A1: ABC-XYZ classification
A2: ABC = value (cumulative share of net sales, last 52 weeks). XYZ = predictability (CV of weekly demand, last 52 weeks). Limits come from Inputs.
A4: Stock code | B4: Description | C4: Net sales 52w (£) | D4: Value rank | E4: Cumulative value share | F4: ABC | G4: Avg weekly demand | H4: Std dev weekly | I4: CV | J4: XYZ | K4: Class | L4: Christmas uplift | M4: Seasonal? | N4: Avg selling price (£) | O4: Same as SQL/ Python? | P4: 9-box matrix: number of SKUs (COUNTIFS)
A5: =SKU_Data!A5 -> 22423 | B5: =_xlfn.XLOOKUP(A5,SKUList,SKU_Data!$B$5:$B$154) -> REGENCY CAKESTAND 3 TIER | C5: =_xlfn.XLOOKUP(A5,SKUList,SKU_Data!$E$5:$E$154) -> 160270.37 | D5: =_xlfn.RANK.EQ(C5,$C$5:$C$154) -> 1 | E5: =SUMIFS($C$5:$C$154,$C$5:$C$154,">="&C5)/SUM($C$5:$C$154) -> 0.050076703 | F5: =IF(E5<=A_Limit,"A",IF(E5<=B_Limit,"B","C")) -> A | G5: =AVERAGE(_xlfn.XLOOKUP(A5,DemandCodes,DemandLast52)) -> 244.40385 | H5: =_xlfn.STDEV.S(_xlfn.XLOOKUP(A5,DemandCodes,DemandLast52)) -> 157.82943 | I5: =H5/G5 -> 0.64577309 | J5: =IF(I5<=X_Limit,"X",IF(I5<=Y_Limit,"Y","Z")) -> X | K5: =F5&J5 -> AX | L5: =AVERAGE(_xlfn.XLOOKUP(A5,DemandCodes,DemandPeak2010))/AVERAGE(_xlfn.XLOOKUP(A5,DemandCodes,DemandTrain)) -> 1.9313203 | M5: =IF(L5>=SeasonalLimit,"Yes","No") -> Yes | N5: =_xlfn.XLOOKUP(A5,SKUList,SKU_Data!$C$5:$C$154)/_xlfn.XLOOKUP(A5,SKUList,SKU_Data!$D$5:$D$154) -> 12.531381 | O5: =IF(K5=_xlfn.XLOOKUP(A5,SKUList,SKU_Data!$F$5:$F$154),"✓","≠") -> ✓ | Q5: X (steady) | R5: Y (variable) | S5: Z (erratic) | T5: Total
A6: =SKU_Data!A6 -> 85123A | B6: =_xlfn.XLOOKUP(A6,SKUList,SKU_Data!$B$5:$B$154) -> WHITE HANGING HEART T-LIGHT HOLDER | C6: =_xlfn.XLOOKUP(A6,SKUList,SKU_Data!$E$5:$E$154) -> 97727.17 | D6: =_xlfn.RANK.EQ(C6,$C$5:$C$154) -> 2 | E6: =SUMIFS($C$5:$C$154,$C$5:$C$154,">="&C6)/SUM($C$5:$C$154) -> 0.080611695 | F6: =IF(E6<=A_Limit,"A",IF(E6<=B_Limit,"B","C")) -> A | G6: =AVERAGE(_xlfn.XLOOKUP(A6,DemandCodes,DemandLast52)) -> 665.01923 | H6: =_xlfn.STDEV.S(_xlfn.XLOOKUP(A6,DemandCodes,DemandLast52)) -> 519.54797 | I6: =H6/G6 -> 0.78125256 | J6: =IF(I6<=X_Limit,"X",IF(I6<=Y_Limit,"Y","Z")) -> Y | K6: =F6&J6 -> AY | L6: =AVERAGE(_xlfn.XLOOKUP(A6,DemandCodes,DemandPeak2010))/AVERAGE(_xlfn.XLOOKUP(A6,DemandCodes,DemandTrain)) -> 1.3546089 | M6: =IF(L6>=SeasonalLimit,"Yes","No") -> Yes | N6: =_xlfn.XLOOKUP(A6,SKUList,SKU_Data!$C$5:$C$154)/_xlfn.XLOOKUP(A6,SKUList,SKU_Data!$D$5:$D$154) -> 2.8082491 | O6: =IF(K6=_xlfn.XLOOKUP(A6,SKUList,SKU_Data!$F$5:$F$154),"✓","≠") -> ✓ | P6: A | Q6: =COUNTIFS(ClsABC,$P6,ClsXYZ,"X") -> 36 | R6: =COUNTIFS(ClsABC,$P6,ClsXYZ,"Y") -> 31 | S6: =COUNTIFS(ClsABC,$P6,ClsXYZ,"Z") -> 28 | T6: =SUM(Q6:S6) -> 95
A7: =SKU_Data!A7 -> 47566 | B7: =_xlfn.XLOOKUP(A7,SKUList,SKU_Data!$B$5:$B$154) -> PARTY BUNTING | C7: =_xlfn.XLOOKUP(A7,SKUList,SKU_Data!$E$5:$E$154) -> 97325.28 | D7: =_xlfn.RANK.EQ(C7,$C$5:$C$154) -> 3 | E7: =SUMIFS($C$5:$C$154,$C$5:$C$154,">="&C7)/SUM($C$5:$C$154) -> 0.11102112 | F7: =IF(E7<=A_Limit,"A",IF(E7<=B_Limit,"B","C")) -> A | G7: =AVERAGE(_xlfn.XLOOKUP(A7,DemandCodes,DemandLast52)) -> 343.88462 | H7: =_xlfn.STDEV.S(_xlfn.XLOOKUP(A7,DemandCodes,DemandLast52)) -> 253.99326 | I7: =H7/G7 -> 0.73860023 | J7: =IF(I7<=X_Limit,"X",IF(I7<=Y_Limit,"Y","Z")) -> X | K7: =F7&J7 -> AX | L7: =AVERAGE(_xlfn.XLOOKUP(A7,DemandCodes,DemandPeak2010))/AVERAGE(_xlfn.XLOOKUP(A7,DemandCodes,DemandTrain)) -> 0.6947788 | M7: =IF(L7>=SeasonalLimit,"Yes","No") -> No | N7: =_xlfn.XLOOKUP(A7,SKUList,SKU_Data!$C$5:$C$154)/_xlfn.XLOOKUP(A7,SKUList,SKU_Data!$D$5:$D$154) -> 5.425774 | O7: =IF(K7=_xlfn.XLOOKUP(A7,SKUList,SKU_Data!$F$5:$F$154),"✓","≠") -> ✓ | P7: B | Q7: =COUNTIFS(ClsABC,$P7,ClsXYZ,"X") -> 10 | R7: =COUNTIFS(ClsABC,$P7,ClsXYZ,"Y") -> 17 | S7: =COUNTIFS(ClsABC,$P7,ClsXYZ,"Z") -> 12 | T7: =SUM(Q7:S7) -> 39
A8: =SKU_Data!A8 -> 85099B | B8: =_xlfn.XLOOKUP(A8,SKUList,SKU_Data!$B$5:$B$154) -> JUMBO BAG RED RETROSPOT | C8: =_xlfn.XLOOKUP(A8,SKUList,SKU_Data!$E$5:$E$154) -> 90869.71 | D8: =_xlfn.RANK.EQ(C8,$C$5:$C$154) -> 4 | E8: =SUMIFS($C$5:$C$154,$C$5:$C$154,">="&C8)/SUM($C$5:$C$154) -> 0.13941349 | F8: =IF(E8<=A_Limit,"A",IF(E8<=B_Limit,"B","C")) -> A | G8: =AVERAGE(_xlfn.XLOOKUP(A8,DemandCodes,DemandLast52)) -> 900.42308 | H8: =_xlfn.STDEV.S(_xlfn.XLOOKUP(A8,DemandCodes,DemandLast52)) -> 493.56249 | I8: =H8/G8 -> 0.5481451 | J8: =IF(I8<=X_Limit,"X",IF(I8<=Y_Limit,"Y","Z")) -> X | K8: =F8&J8 -> AX | L8: =AVERAGE(_xlfn.XLOOKUP(A8,DemandCodes,DemandPeak2010))/AVERAGE(_xlfn.XLOOKUP(A8,DemandCodes,DemandTrain)) -> 1.4922836 | M8: =IF(L8>=SeasonalLimit,"Yes","No") -> Yes | N8: =_xlfn.XLOOKUP(A8,SKUList,SKU_Data!$C$5:$C$154)/_xlfn.XLOOKUP(A8,SKUList,SKU_Data!$D$5:$D$154) -> 1.9369511 | O8: =IF(K8=_xlfn.XLOOKUP(A8,SKUList,SKU_Data!$F$5:$F$154),"✓","≠") -> ✓ | P8: C | Q8: =COUNTIFS(ClsABC,$P8,ClsXYZ,"X") -> 5 | R8: =COUNTIFS(ClsABC,$P8,ClsXYZ,"Y") -> 7 | S8: =COUNTIFS(ClsABC,$P8,ClsXYZ,"Z") -> 4 | T8: =SUM(Q8:S8) -> 16
A9: =SKU_Data!A9 -> 84879 | B9: =_xlfn.XLOOKUP(A9,SKUList,SKU_Data!$B$5:$B$154) -> ASSORTED COLOUR BIRD ORNAMENT | C9: =_xlfn.XLOOKUP(A9,SKUList,SKU_Data!$E$5:$E$154) -> 56285.16 | D9: =_xlfn.RANK.EQ(C9,$C$5:$C$154) -> 5 | E9: =SUMIFS($C$5:$C$154,$C$5:$C$154,">="&C9)/SUM($C$5:$C$154) -> 0.15699986 | F9: =IF(E9<=A_Limit,"A",IF(E9<=B_Limit,"B","C")) -> A | G9: =AVERAGE(_xlfn.XLOOKUP(A9,DemandCodes,DemandLast52)) -> 667.76923 | H9: =_xlfn.STDEV.S(_xlfn.XLOOKUP(A9,DemandCodes,DemandLast52)) -> 560.66958 | I9: =H9/G9 -> 0.83961577 | J9: =IF(I9<=X_Limit,"X",IF(I9<=Y_Limit,"Y","Z")) -> Y | K9: =F9&J9 -> AY | L9: =AVERAGE(_xlfn.XLOOKUP(A9,DemandCodes,DemandPeak2010))/AVERAGE(_xlfn.XLOOKUP(A9,DemandCodes,DemandTrain)) -> 2.0484386 | M9: =IF(L9>=SeasonalLimit,"Yes","No") -> Yes | N9: =_xlfn.XLOOKUP(A9,SKUList,SKU_Data!$C$5:$C$154)/_xlfn.XLOOKUP(A9,SKUList,SKU_Data!$D$5:$D$154) -> 1.6200477 | O9: =IF(K9=_xlfn.XLOOKUP(A9,SKUList,SKU_Data!$F$5:$F$154),"✓","≠") -> ✓ | P9: Total | Q9: =SUM(Q6:Q8) -> 51 | R9: =SUM(R6:R8) -> 55 | S9: =SUM(S6:S8) -> 44 | T9: =SUM(T6:T8) -> 150
A10: =SKU_Data!A10 -> 22086 | B10: =_xlfn.XLOOKUP(A10,SKUList,SKU_Data!$B$5:$B$154) -> PAPER CHAIN KIT 50'S CHRISTMAS | C10: =_xlfn.XLOOKUP(A10,SKUList,SKU_Data!$E$5:$E$154) -> 55727.95 | D10: =_xlfn.RANK.EQ(C10,$C$5:$C$154) -> 6 | E10: =SUMIFS($C$5:$C$154,$C$5:$C$154,">="&C10)/SUM($C$5:$C$154) -> 0.17441214 | F10: =IF(E10<=A_Limit,"A",IF(E10<=B_Limit,"B","C")) -> A | G10: =AVERAGE(_xlfn.XLOOKUP(A10,DemandCodes,DemandLast52)) -> 313.82692 | H10: =_xlfn.STDEV.S(_xlfn.XLOOKUP(A10,DemandCodes,DemandLast52)) -> 522.61637 | I10: =H10/G10 -> 1.6653013 | J10: =IF(I10<=X_Limit,"X",IF(I10<=Y_Limit,"Y","Z")) -> Z | K10: =F10&J10 -> AZ | L10: =AVERAGE(_xlfn.XLOOKUP(A10,DemandCodes,DemandPeak2010))/AVERAGE(_xlfn.XLOOKUP(A10,DemandCodes,DemandTrain)) -> 4.8464339 | M10: =IF(L10>=SeasonalLimit,"Yes","No") -> Yes | N10: =_xlfn.XLOOKUP(A10,SKUList,SKU_Data!$C$5:$C$154)/_xlfn.XLOOKUP(A10,SKUList,SKU_Data!$D$5:$D$154) -> 3.3983453 | O10: =IF(K10=_xlfn.XLOOKUP(A10,SKUList,SKU_Data!$F$5:$F$154),"✓","≠") -> ✓
A11: =SKU_Data!A11 -> 79321 | B11: =_xlfn.XLOOKUP(A11,SKUList,SKU_Data!$B$5:$B$154) -> CHILLI LIGHTS | C11: =_xlfn.XLOOKUP(A11,SKUList,SKU_Data!$E$5:$E$154) -> 51524.91 | D11: =_xlfn.RANK.EQ(C11,$C$5:$C$154) -> 7 | E11: =SUMIFS($C$5:$C$154,$C$5:$C$154,">="&C11)/SUM($C$5:$C$154) -> 0.19051117 | F11: =IF(E11<=A_Limit,"A",IF(E11<=B_Limit,"B","C")) -> A | G11: =AVERAGE(_xlfn.XLOOKUP(A11,DemandCodes,DemandLast52)) -> 189.92308 | H11: =_xlfn.STDEV.S(_xlfn.XLOOKUP(A11,DemandCodes,DemandLast52)) -> 226.97049 | I11: =H11/G11 -> 1.1950653 | J11: =IF(I11<=X_Limit,"X",IF(I11<=Y_Limit,"Y","Z")) -> Y | K11: =F11&J11 -> AY | L11: =AVERAGE(_xlfn.XLOOKUP(A11,DemandCodes,DemandPeak2010))/AVERAGE(_xlfn.XLOOKUP(A11,DemandCodes,DemandTrain)) -> 2.1948041 | M11: =IF(L11>=SeasonalLimit,"Yes","No") -> Yes | N11: =_xlfn.XLOOKUP(A11,SKUList,SKU_Data!$C$5:$C$154)/_xlfn.XLOOKUP(A11,SKUList,SKU_Data!$D$5:$D$154) -> 5.2103325 | O11: =IF(K11=_xlfn.XLOOKUP(A11,SKUList,SKU_Data!$F$5:$F$154),"✓","≠") -> ✓ | P11: 9-box matrix: share of sales value (SUMIFS)
A12: =SKU_Data!A12 -> 22502 | B12: =_xlfn.XLOOKUP(A12,SKUList,SKU_Data!$B$5:$B$154) -> PICNIC BASKET WICKER SMALL | C12: =_xlfn.XLOOKUP(A12,SKUList,SKU_Data!$E$5:$E$154) -> 51315.59 | D12: =_xlfn.RANK.EQ(C12,$C$5:$C$154) -> 8 | E12: =SUMIFS($C$5:$C$154,$C$5:$C$154,">="&C12)/SUM($C$5:$C$154) -> 0.2065448 | F12: =IF(E12<=A_Limit,"A",IF(E12<=B_Limit,"B","C")) -> A | G12: =AVERAGE(_xlfn.XLOOKUP(A12,DemandCodes,DemandLast52)) -> 36.673077 | H12: =_xlfn.STDEV.S(_xlfn.XLOOKUP(A12,DemandCodes,DemandLast52)) -> 48.335316 | I12: =H12/G12 -> 1.3180055 | J12: =IF(I12<=X_Limit,"X",IF(I12<=Y_Limit,"Y","Z")) -> Z | K12: =F12&J12 -> AZ | L12: =AVERAGE(_xlfn.XLOOKUP(A12,DemandCodes,DemandPeak2010))/AVERAGE(_xlfn.XLOOKUP(A12,DemandCodes,DemandTrain)) -> 1.5039434 | M12: =IF(L12>=SeasonalLimit,"Yes","No") -> Yes | N12: =_xlfn.XLOOKUP(A12,SKUList,SKU_Data!$C$5:$C$154)/_xlfn.XLOOKUP(A12,SKUList,SKU_Data!$D$5:$D$154) -> 26.085187 | O12: =IF(K12=_xlfn.XLOOKUP(A12,SKUList,SKU_Data!$F$5:$F$154),"✓","≠") -> ✓ | Q12: X (steady) | R12: Y (variable) | S12: Z (erratic) | T12: Total
A13: =SKU_Data!A13 -> 22197 | B13: =_xlfn.XLOOKUP(A13,SKUList,SKU_Data!$B$5:$B$154) -> SMALL POPCORN HOLDER | C13: =_xlfn.XLOOKUP(A13,SKUList,SKU_Data!$E$5:$E$154) -> 44426.46 | D13: =_xlfn.RANK.EQ(C13,$C$5:$C$154) -> 9 | E13: =SUMIFS($C$5:$C$154,$C$5:$C$154,">="&C13)/SUM($C$5:$C$154) -> 0.22042591 | F13: =IF(E13<=A_Limit,"A",IF(E13<=B_Limit,"B","C")) -> A | G13: =AVERAGE(_xlfn.XLOOKUP(A13,DemandCodes,DemandLast52)) -> 940.19231 | H13: =_xlfn.STDEV.S(_xlfn.XLOOKUP(A13,DemandCodes,DemandLast52)) -> 942.673 | I13: =H13/G13 -> 1.0026385 | J13: =IF(I13<=X_Limit,"X",IF(I13<=Y_Limit,"Y","Z")) -> Y | K13: =F13&J13 -> AY | L13: =AVERAGE(_xlfn.XLOOKUP(A13,DemandCodes,DemandPeak2010))/AVERAGE(_xlfn.XLOOKUP(A13,DemandCodes,DemandTrain)) -> 2.0594331 | M13: =IF(L13>=SeasonalLimit,"Yes","No") -> Yes | N13: =_xlfn.XLOOKUP(A13,SKUList,SKU_Data!$C$5:$C$154)/_xlfn.XLOOKUP(A13,SKUList,SKU_Data!$D$5:$D$154) -> 0.90749438 | O13: =IF(K13=_xlfn.XLOOKUP(A13,SKUList,SKU_Data!$F$5:$F$154),"✓","≠") -> ✓ | P13: A | Q13: =SUMIFS(ClsValue,ClsABC,$P13,ClsXYZ,"X")/SUM(ClsValue) -> 0.33818547 | R13: =SUMIFS(ClsValue,ClsABC,$P13,ClsXYZ,"Y")/SUM(ClsValue) -> 0.2514302 | S13: =SUMIFS(ClsValue,ClsABC,$P13,ClsXYZ,"Z")/SUM(ClsValue) -> 0.20931421 | T13: =SUM(Q13:S13) -> 0.79892989
A14: =SKU_Data!A14 -> 22386 | B14: =_xlfn.XLOOKUP(A14,SKUList,SKU_Data!$B$5:$B$154) -> JUMBO BAG PINK POLKADOT | C14: =_xlfn.XLOOKUP(A14,SKUList,SKU_Data!$E$5:$E$154) -> 40758.71 | D14: =_xlfn.RANK.EQ(C14,$C$5:$C$154) -> 10 | E14: =SUMIFS($C$5:$C$154,$C$5:$C$154,">="&C14)/SUM($C$5:$C$154) -> 0.23316103 | F14: =IF(E14<=A_Limit,"A",IF(E14<=B_Limit,"B","C")) -> A | G14: =AVERAGE(_xlfn.XLOOKUP(A14,DemandCodes,DemandLast52)) -> 396.30769 | H14: =_xlfn.STDEV.S(_xlfn.XLOOKUP(A14,DemandCodes,DemandLast52)) -> 278.83515 | I14: =H14/G14 -> 0.70358248 | J14: =IF(I14<=X_Limit,"X",IF(I14<=Y_Limit,"Y","Z")) -> X | K14: =F14&J14 -> AX | L14: =AVERAGE(_xlfn.XLOOKUP(A14,DemandCodes,DemandPeak2010))/AVERAGE(_xlfn.XLOOKUP(A14,DemandCodes,DemandTrain)) -> 1.2199262 | M14: =IF(L14>=SeasonalLimit,"Yes","No") -> No | N14: =_xlfn.XLOOKUP(A14,SKUList,SKU_Data!$C$5:$C$154)/_xlfn.XLOOKUP(A14,SKUList,SKU_Data!$D$5:$D$154) -> 1.9737604 | O14: =IF(K14=_xlfn.XLOOKUP(A14,SKUList,SKU_Data!$F$5:$F$154),"✓","≠") -> ✓ | P14: B | Q14: =SUMIFS(ClsValue,ClsABC,$P14,ClsXYZ,"X")/SUM(ClsValue) -> 0.038295451 | R14: =SUMIFS(ClsValue,ClsABC,$P14,ClsXYZ,"Y")/SUM(ClsValue) -> 0.064960964 | S14: =SUMIFS(ClsValue,ClsABC,$P14,ClsXYZ,"Z")/SUM(ClsValue) -> 0.045274381 | T14: =SUM(Q14:S14) -> 0.1485308
A15: =SKU_Data!A15 -> 21137 | B15: =_xlfn.XLOOKUP(A15,SKUList,SKU_Data!$B$5:$B$154) -> BLACK RECORD COVER FRAME | C15: =_xlfn.XLOOKUP(A15,SKUList,SKU_Data!$E$5:$E$154) -> 34577.75 | D15: =_xlfn.RANK.EQ(C15,$C$5:$C$154) -> 11 | E15: =SUMIFS($C$5:$C$154,$C$5:$C$154,">="&C15)/SUM($C$5:$C$154) -> 0.24396489 | F15: =IF(E15<=A_Limit,"A",IF(E15<=B_Limit,"B","C")) -> A | G15: =AVERAGE(_xlfn.XLOOKUP(A15,DemandCodes,DemandLast52)) -> 191.69231 | H15: =_xlfn.STDEV.S(_xlfn.XLOOKUP(A15,DemandCodes,DemandLast52)) -> 227.12004 | I15: =H15/G15 -> 1.1848156 | J15: =IF(I15<=X_Limit,"X",IF(I15<=Y_Limit,"Y","Z")) -> Y | K15: =F15&J15 -> AY | L15: =AVERAGE(_xlfn.XLOOKUP(A15,DemandCodes,DemandPeak2010))/AVERAGE(_xlfn.XLOOKUP(A15,DemandCodes,DemandTrain)) -> 1.9922247 | M15: =IF(L15>=SeasonalLimit,"Yes","No") -> Yes | N15: =_xlfn.XLOOKUP(A15,SKUList,SKU_Data!$C$5:$C$154)/_xlfn.XLOOKUP(A15,SKUList,SKU_Data!$D$5:$D$154) -> 3.4691341 | O15: =IF(K15=_xlfn.XLOOKUP(A15,SKUList,SKU_Data!$F$5:$F$154),"✓","≠") -> ✓ | P15: C | Q15: =SUMIFS(ClsValue,ClsABC,$P15,ClsXYZ,"X")/SUM(ClsValue) -> 0.016630695 | R15: =SUMIFS(ClsValue,ClsABC,$P15,ClsXYZ,"Y")/SUM(ClsValue) -> 0.023013106 | S15: =SUMIFS(ClsValue,ClsABC,$P15,ClsXYZ,"Z")/SUM(ClsValue) -> 0.012895517 | T15: =SUM(Q15:S15) -> 0.052539317
A16: =SKU_Data!A16 -> 20725 | B16: =_xlfn.XLOOKUP(A16,SKUList,SKU_Data!$B$5:$B$154) -> LUNCH BAG RED RETROSPOT | C16: =_xlfn.XLOOKUP(A16,SKUList,SKU_Data!$E$5:$E$154) -> 33896.01 | D16: =_xlfn.RANK.EQ(C16,$C$5:$C$154) -> 12 | E16: =SUMIFS($C$5:$C$154,$C$5:$C$154,">="&C16)/SUM($C$5:$C$154) -> 0.25455575 | F16: =IF(E16<=A_Limit,"A",IF(E16<=B_Limit,"B","C")) -> A | G16: =AVERAGE(_xlfn.XLOOKUP(A16,DemandCodes,DemandLast52)) -> 352.61538 | H16: =_xlfn.STDEV.S(_xlfn.XLOOKUP(A16,DemandCodes,DemandLast52)) -> 174.64969 | I16: =H16/G16 -> 0.495298 | J16: =IF(I16<=X_Limit,"X",IF(I16<=Y_Limit,"Y","Z")) -> X | K16: =F16&J16 -> AX | L16: =AVERAGE(_xlfn.XLOOKUP(A16,DemandCodes,DemandPeak2010))/AVERAGE(_xlfn.XLOOKUP(A16,DemandCodes,DemandTrain)) -> 1.0244654 | M16: =IF(L16>=SeasonalLimit,"Yes","No") -> No | N16: =_xlfn.XLOOKUP(A16,SKUList,SKU_Data!$C$5:$C$154)/_xlfn.XLOOKUP(A16,SKUList,SKU_Data!$D$5:$D$154) -> 1.8376697 | O16: =IF(K16=_xlfn.XLOOKUP(A16,SKUList,SKU_Data!$F$5:$F$154),"✓","≠") -> ✓ | P16: Total | Q16: =SUM(Q13:Q15) -> 0.39311162 | R16: =SUM(R13:R15) -> 0.33940427 | S16: =SUM(S13:S15) -> 0.26748411 | T16: =SUM(T13:T15) -> 1
A17: =SKU_Data!A17 -> 82484 | B17: =_xlfn.XLOOKUP(A17,SKUList,SKU_Data!$B$5:$B$154) -> WOOD BLACK BOARD ANT WHITE FINISH | C17: =_xlfn.XLOOKUP(A17,SKUList,SKU_Data!$E$5:$E$154) -> 33229.4 | D17: =_xlfn.RANK.EQ(C17,$C$5:$C$154) -> 13 | E17: =SUMIFS($C$5:$C$154,$C$5:$C$154,">="&C17)/SUM($C$5:$C$154) -> 0.26493832 | F17: =IF(E17<=A_Limit,"A",IF(E17<=B_Limit,"B","C")) -> A | G17: =AVERAGE(_xlfn.XLOOKUP(A17,DemandCodes,DemandLast52)) -> 107.09615 | H17: =_xlfn.STDEV.S(_xlfn.XLOOKUP(A17,DemandCodes,DemandLast52)) -> 171.62422 | I17: =H17/G17 -> 1.6025246 | J17: =IF(I17<=X_Limit,"X",IF(I17<=Y_Limit,"Y","Z")) -> Z | K17: =F17&J17 -> AZ | L17: =AVERAGE(_xlfn.XLOOKUP(A17,DemandCodes,DemandPeak2010))/AVERAGE(_xlfn.XLOOKUP(A17,DemandCodes,DemandTrain)) -> 1.37031 | M17: =IF(L17>=SeasonalLimit,"Yes","No") -> Yes | N17: =_xlfn.XLOOKUP(A17,SKUList,SKU_Data!$C$5:$C$154)/_xlfn.XLOOKUP(A17,SKUList,SKU_Data!$D$5:$D$154) -> 5.9711053 | O17: =IF(K17=_xlfn.XLOOKUP(A17,SKUList,SKU_Data!$F$5:$F$154),"✓","≠") -> ✓
A18: =SKU_Data!A18 -> 85099F | B18: =_xlfn.XLOOKUP(A18,SKUList,SKU_Data!$B$5:$B$154) -> JUMBO BAG STRAWBERRY | C18: =_xlfn.XLOOKUP(A18,SKUList,SKU_Data!$E$5:$E$154) -> 31496.69 | D18: =_xlfn.RANK.EQ(C18,$C$5:$C$154) -> 14 | E18: =SUMIFS($C$5:$C$154,$C$5:$C$154,">="&C18)/SUM($C$5:$C$154) -> 0.27477951 | F18: =IF(E18<=A_Limit,"A",IF(E18<=B_Limit,"B","C")) -> A | G18: =AVERAGE(_xlfn.XLOOKUP(A18,DemandCodes,DemandLast52)) -> 319.53846 | H18: =_xlfn.STDEV.S(_xlfn.XLOOKUP(A18,DemandCodes,DemandLast52)) -> 250.01909 | I18: =H18/G18 -> 0.78243819 | J18: =IF(I18<=X_Limit,"X",IF(I18<=Y_Limit,"Y","Z")) -> Y | K18: =F18&J18 -> AY | L18: =AVERAGE(_xlfn.XLOOKUP(A18,DemandCodes,DemandPeak2010))/AVERAGE(_xlfn.XLOOKUP(A18,DemandCodes,DemandTrain)) -> 1.0156457 | M18: =IF(L18>=SeasonalLimit,"Yes","No") -> No | N18: =_xlfn.XLOOKUP(A18,SKUList,SKU_Data!$C$5:$C$154)/_xlfn.XLOOKUP(A18,SKUList,SKU_Data!$D$5:$D$154) -> 1.8940468 | O18: =IF(K18=_xlfn.XLOOKUP(A18,SKUList,SKU_Data!$F$5:$F$154),"✓","≠") -> ✓ | P18: How to read it
A19: =SKU_Data!A19 -> 22469 | B19: =_xlfn.XLOOKUP(A19,SKUList,SKU_Data!$B$5:$B$154) -> HEART OF WICKER SMALL | C19: =_xlfn.XLOOKUP(A19,SKUList,SKU_Data!$E$5:$E$154) -> 30715.45 | D19: =_xlfn.RANK.EQ(C19,$C$5:$C$154) -> 15 | E19: =SUMIFS($C$5:$C$154,$C$5:$C$154,">="&C19)/SUM($C$5:$C$154) -> 0.28437659 | F19: =IF(E19<=A_Limit,"A",IF(E19<=B_Limit,"B","C")) -> A | G19: =AVERAGE(_xlfn.XLOOKUP(A19,DemandCodes,DemandLast52)) -> 331.48077 | H19: =_xlfn.STDEV.S(_xlfn.XLOOKUP(A19,DemandCodes,DemandLast52)) -> 332.30712 | I19: =H19/G19 -> 1.0024929 | J19: =IF(I19<=X_Limit,"X",IF(I19<=Y_Limit,"Y","Z")) -> Y | K19: =F19&J19 -> AY | L19: =AVERAGE(_xlfn.XLOOKUP(A19,DemandCodes,DemandPeak2010))/AVERAGE(_xlfn.XLOOKUP(A19,DemandCodes,DemandTrain)) -> 1.4407266 | M19: =IF(L19>=SeasonalLimit,"Yes","No") -> Yes | N19: =_xlfn.XLOOKUP(A19,SKUList,SKU_Data!$C$5:$C$154)/_xlfn.XLOOKUP(A19,SKUList,SKU_Data!$D$5:$D$154) -> 1.7802038 | O19: =IF(K19=_xlfn.XLOOKUP(A19,SKUList,SKU_Data!$F$5:$F$154),"✓","≠") -> ✓ | P19: AX = valuable and steady: easy to forecast, keep lean stock.
A20: =SKU_Data!A20 -> 22178 | B20: =_xlfn.XLOOKUP(A20,SKUList,SKU_Data!$B$5:$B$154) -> VICTORIAN GLASS HANGING T-LIGHT | C20: =_xlfn.XLOOKUP(A20,SKUList,SKU_Data!$E$5:$E$154) -> 30004.53 | D20: =_xlfn.RANK.EQ(C20,$C$5:$C$154) -> 16 | E20: =SUMIFS($C$5:$C$154,$C$5:$C$154,">="&C20)/SUM($C$5:$C$154) -> 0.29375155 | F20: =IF(E20<=A_Limit,"A",IF(E20<=B_Limit,"B","C")) -> A | G20: =AVERAGE(_xlfn.XLOOKUP(A20,DemandCodes,DemandLast52)) -> 433.98077 | H20: =_xlfn.STDEV.S(_xlfn.XLOOKUP(A20,DemandCodes,DemandLast52)) -> 278.41819 | I20: =H20/G20 -> 0.64154498 | J20: =IF(I20<=X_Limit,"X",IF(I20<=Y_Limit,"Y","Z")) -> X | K20: =F20&J20 -> AX | L20: =AVERAGE(_xlfn.XLOOKUP(A20,DemandCodes,DemandPeak2010))/AVERAGE(_xlfn.XLOOKUP(A20,DemandCodes,DemandTrain)) -> 1.6354751 | M20: =IF(L20>=SeasonalLimit,"Yes","No") -> Yes | N20: =_xlfn.XLOOKUP(A20,SKUList,SKU_Data!$C$5:$C$154)/_xlfn.XLOOKUP(A20,SKUList,SKU_Data!$D$5:$D$154) -> 1.3309946 | O20: =IF(K20=_xlfn.XLOOKUP(A20,SKUList,SKU_Data!$F$5:$F$154),"✓","≠") -> ✓ | P20: AZ = valuable but erratic: the risky box; needs the most safety stock and attention.
A21: =SKU_Data!A21 -> 21931 | B21: =_xlfn.XLOOKUP(A21,SKUList,SKU_Data!$B$5:$B$154) -> JUMBO STORAGE BAG SUKI | C21: =_xlfn.XLOOKUP(A21,SKUList,SKU_Data!$E$5:$E$154) -> 29521.44 | D21: =_xlfn.RANK.EQ(C21,$C$5:$C$154) -> 17 | E21: =SUMIFS($C$5:$C$154,$C$5:$C$154,">="&C21)/SUM($C$5:$C$154) -> 0.30297557 | F21: =IF(E21<=A_Limit,"A",IF(E21<=B_Limit,"B","C")) -> A | G21: =AVERAGE(_xlfn.XLOOKUP(A21,DemandCodes,DemandLast52)) -> 250.63462 | H21: =_xlfn.STDEV.S(_xlfn.XLOOKUP(A21,DemandCodes,DemandLast52)) -> 113.00391 | I21: =H21/G21 -> 0.45087112 | J21: =IF(I21<=X_Limit,"X",IF(I21<=Y_Limit,"Y","Z")) -> X | K21: =F21&J21 -> AX | L21: =AVERAGE(_xlfn.XLOOKUP(A21,DemandCodes,DemandPeak2010))/AVERAGE(_xlfn.XLOOKUP(A21,DemandCodes,DemandTrain)) -> 1.2146196 | M21: =IF(L21>=SeasonalLimit,"Yes","No") -> No | N21: =_xlfn.XLOOKUP(A21,SKUList,SKU_Data!$C$5:$C$154)/_xlfn.XLOOKUP(A21,SKUList,SKU_Data!$D$5:$D$154) -> 2.2536054 | O21: =IF(K21=_xlfn.XLOOKUP(A21,SKUList,SKU_Data!$F$5:$F$154),"✓","≠") -> ✓ | P21: CZ = low value and erratic: candidates for make-to-order or delisting.
A22: =SKU_Data!A22 -> 22112 | B22: =_xlfn.XLOOKUP(A22,SKUList,SKU_Data!$B$5:$B$154) -> CHOCOLATE HOT WATER BOTTLE | C22: =_xlfn.XLOOKUP(A22,SKUList,SKU_Data!$E$5:$E$154) -> 28625.99 | D22: =_xlfn.RANK.EQ(C22,$C$5:$C$154) -> 18 | E22: =SUMIFS($C$5:$C$154,$C$5:$C$154,">="&C22)/SUM($C$5:$C$154) -> 0.3119198 | F22: =IF(E22<=A_Limit,"A",IF(E22<=B_Limit,"B","C")) -> A | G22: =AVERAGE(_xlfn.XLOOKUP(A22,DemandCodes,DemandLast52)) -> 101.36538 | H22: =_xlfn.STDEV.S(_xlfn.XLOOKUP(A22,DemandCodes,DemandLast52)) -> 133.41576 | I22: =H22/G22 -> 1.3161866 | J22: =IF(I22<=X_Limit,"X",IF(I22<=Y_Limit,"Y","Z")) -> Z | K22: =F22&J22 -> AZ | L22: =AVERAGE(_xlfn.XLOOKUP(A22,DemandCodes,DemandPeak2010))/AVERAGE(_xlfn.XLOOKUP(A22,DemandCodes,DemandTrain)) -> 3.1597499 | M22: =IF(L22>=SeasonalLimit,"Yes","No") -> Yes | N22: =_xlfn.XLOOKUP(A22,SKUList,SKU_Data!$C$5:$C$154)/_xlfn.XLOOKUP(A22,SKUList,SKU_Data!$D$5:$D$154) -> 5.4037544 | O22: =IF(K22=_xlfn.XLOOKUP(A22,SKUList,SKU_Data!$F$5:$F$154),"✓","≠") -> ✓ | P22: Check vs SQL/Python (default limits only): | T22: =COUNTIF($O$5:$O$154,"✓")&" / 150 match" -> 150 / 150 match
A23: =SKU_Data!A23 -> 22114 | B23: =_xlfn.XLOOKUP(A23,SKUList,SKU_Data!$B$5:$B$154) -> HOT WATER BOTTLE TEA AND SYMPATHY | C23: =_xlfn.XLOOKUP(A23,SKUList,SKU_Data!$E$5:$E$154) -> 28284.91 | D23: =_xlfn.RANK.EQ(C23,$C$5:$C$154) -> 19 | E23: =SUMIFS($C$5:$C$154,$C$5:$C$154,">="&C23)/SUM($C$5:$C$154) -> 0.32075746 | F23: =IF(E23<=A_Limit,"A",IF(E23<=B_Limit,"B","C")) -> A | G23: =AVERAGE(_xlfn.XLOOKUP(A23,DemandCodes,DemandLast52)) -> 94.653846 | H23: =_xlfn.STDEV.S(_xlfn.XLOOKUP(A23,DemandCodes,DemandLast52)) -> 161.55129 | I23: =H23/G23 -> 1.7067588 | J23: =IF(I23<=X_Limit,"X",IF(I23<=Y_Limit,"Y","Z")) -> Z | K23: =F23&J23 -> AZ | L23: =AVERAGE(_xlfn.XLOOKUP(A23,DemandCodes,DemandPeak2010))/AVERAGE(_xlfn.XLOOKUP(A23,DemandCodes,DemandTrain)) -> 3.3254182 | M23: =IF(L23>=SeasonalLimit,"Yes","No") -> Yes | N23: =_xlfn.XLOOKUP(A23,SKUList,SKU_Data!$C$5:$C$154)/_xlfn.XLOOKUP(A23,SKUList,SKU_Data!$D$5:$D$154) -> 5.7144305 | O23: =IF(K23=_xlfn.XLOOKUP(A23,SKUList,SKU_Data!$F$5:$F$154),"✓","≠") -> ✓
A24: =SKU_Data!A24 -> 22470 | B24: =_xlfn.XLOOKUP(A24,SKUList,SKU_Data!$B$5:$B$154) -> HEART OF WICKER LARGE | C24: =_xlfn.XLOOKUP(A24,SKUList,SKU_Data!$E$5:$E$154) -> 27315.13 | D24: =_xlfn.RANK.EQ(C24,$C$5:$C$154) -> 20 | E24: =SUMIFS($C$5:$C$154,$C$5:$C$154,">="&C24)/SUM($C$5:$C$154) -> 0.32929211 | F24: =IF(E24<=A_Limit,"A",IF(E24<=B_Limit,"B","C")) -> A | G24: =AVERAGE(_xlfn.XLOOKUP(A24,DemandCodes,DemandLast52)) -> 173.32692 | H24: =_xlfn.STDEV.S(_xlfn.XLOOKUP(A24,DemandCodes,DemandLast52)) -> 249.91424 | I24: =H24/G24 -> 1.4418662 | J24: =IF(I24<=X_Limit,"X",IF(I24<=Y_Limit,"Y","Z")) -> Z | K24: =F24&J24 -> AZ | L24: =AVERAGE(_xlfn.XLOOKUP(A24,DemandCodes,DemandPeak2010))/AVERAGE(_xlfn.XLOOKUP(A24,DemandCodes,DemandTrain)) -> 2.1773857 | M24: =IF(L24>=SeasonalLimit,"Yes","No") -> Yes | N24: =_xlfn.XLOOKUP(A24,SKUList,SKU_Data!$C$5:$C$154)/_xlfn.XLOOKUP(A24,SKUList,SKU_Data!$D$5:$D$154) -> 3.0286393 | O24: =IF(K24=_xlfn.XLOOKUP(A24,SKUList,SKU_Data!$F$5:$F$154),"✓","≠") -> ✓
A25: =SKU_Data!A25 -> 22411 | B25: =_xlfn.XLOOKUP(A25,SKUList,SKU_Data!$B$5:$B$154) -> JUMBO SHOPPER VINTAGE RED PAISLEY | C25: =_xlfn.XLOOKUP(A25,SKUList,SKU_Data!$E$5:$E$154) -> 26756.59 | D25: =_xlfn.RANK.EQ(C25,$C$5:$C$154) -> 21 | E25: =SUMIFS($C$5:$C$154,$C$5:$C$154,">="&C25)/SUM($C$5:$C$154) -> 0.33765224 | F25: =IF(E25<=A_Limit,"A",IF(E25<=B_Limit,"B","C")) -> A | G25: =AVERAGE(_xlfn.XLOOKUP(A25,DemandCodes,DemandLast52)) -> 224.19231 | H25: =_xlfn.STDEV.S(_xlfn.XLOOKUP(A25,DemandCodes,DemandLast52)) -> 129.38892 | I25: =H25/G25 -> 0.57713361 | J25: =IF(I25<=X_Limit,"X",IF(I25<=Y_Limit,"Y","Z")) -> X | K25: =F25&J25 -> AX | L25: =AVERAGE(_xlfn.XLOOKUP(A25,DemandCodes,DemandPeak2010))/AVERAGE(_xlfn.XLOOKUP(A25,DemandCodes,DemandTrain)) -> 1.574114 | M25: =IF(L25>=SeasonalLimit,"Yes","No") -> Yes | N25: =_xlfn.XLOOKUP(A25,SKUList,SKU_Data!$C$5:$C$154)/_xlfn.XLOOKUP(A25,SKUList,SKU_Data!$D$5:$D$154) -> 2.279309 | O25: =IF(K25=_xlfn.XLOOKUP(A25,SKUList,SKU_Data!$F$5:$F$154),"✓","≠") -> ✓
A26: =SKU_Data!A26 -> 22355 | B26: =_xlfn.XLOOKUP(A26,SKUList,SKU_Data!$B$5:$B$154) -> CHARLOTTE BAG SUKI DESIGN | C26: =_xlfn.XLOOKUP(A26,SKUList,SKU_Data!$E$5:$E$154) -> 26739.4 | D26: =_xlfn.RANK.EQ(C26,$C$5:$C$154) -> 22 | E26: =SUMIFS($C$5:$C$154,$C$5:$C$154,">="&C26)/SUM($C$5:$C$154) -> 0.34600701 | F26: =IF(E26<=A_Limit,"A",IF(E26<=B_Limit,"B","C")) -> A | G26: =AVERAGE(_xlfn.XLOOKUP(A26,DemandCodes,DemandLast52)) -> 323.69231 | H26: =_xlfn.STDEV.S(_xlfn.XLOOKUP(A26,DemandCodes,DemandLast52)) -> 152.94348 | I26: =H26/G26 -> 0.47249649 | J26: =IF(I26<=X_Limit,"X",IF(I26<=Y_Limit,"Y","Z")) -> X | K26: =F26&J26 -> AX | L26: =AVERAGE(_xlfn.XLOOKUP(A26,DemandCodes,DemandPeak2010))/AVERAGE(_xlfn.XLOOKUP(A26,DemandCodes,DemandTrain)) -> 1.4400386 | M26: =IF(L26>=SeasonalLimit,"Yes","No") -> Yes | N26: =_xlfn.XLOOKUP(A26,SKUList,SKU_Data!$C$5:$C$154)/_xlfn.XLOOKUP(A26,SKUList,SKU_Data!$D$5:$D$154) -> 1.5813126 | O26: =IF(K26=_xlfn.XLOOKUP(A26,SKUList,SKU_Data!$F$5:$F$154),"✓","≠") -> ✓
A27: =SKU_Data!A27 -> 20685 | B27: =_xlfn.XLOOKUP(A27,SKUList,SKU_Data!$B$5:$B$154) -> DOORMAT RED RETROSPOT | C27: =_xlfn.XLOOKUP(A27,SKUList,SKU_Data!$E$5:$E$154) -> 26531.03 | D27: =_xlfn.RANK.EQ(C27,$C$5:$C$154) -> 23 | E27: =SUMIFS($C$5:$C$154,$C$5:$C$154,">="&C27)/SUM($C$5:$C$154) -> 0.35429666 | F27: =IF(E27<=A_Limit,"A",IF(E27<=B_Limit,"B","C")) -> A | G27: =AVERAGE(_xlfn.XLOOKUP(A27,DemandCodes,DemandLast52)) -> 74.615385 | H27: =_xlfn.STDEV.S(_xlfn.XLOOKUP(A27,DemandCodes,DemandLast52)) -> 96.675555 | I27: =H27/G27 -> 1.2956518 | J27: =IF(I27<=X_Limit,"X",IF(I27<=Y_Limit,"Y","Z")) -> Z | K27: =F27&J27 -> AZ | L27: =AVERAGE(_xlfn.XLOOKUP(A27,DemandCodes,DemandPeak2010))/AVERAGE(_xlfn.XLOOKUP(A27,DemandCodes,DemandTrain)) -> 1.0686052 | M27: =IF(L27>=SeasonalLimit,"Yes","No") -> No | N27: =_xlfn.XLOOKUP(A27,SKUList,SKU_Data!$C$5:$C$154)/_xlfn.XLOOKUP(A27,SKUList,SKU_Data!$D$5:$D$154) -> 6.840408 | O27: =IF(K27=_xlfn.XLOOKUP(A27,SKUList,SKU_Data!$F$5:$F$154),"✓","≠") -> ✓
A28: =SKU_Data!A28 -> 85099C | B28: =_xlfn.XLOOKUP(A28,SKUList,SKU_Data!$B$5:$B$154) -> JUMBO BAG BAROQUE BLACK WHITE | C28: =_xlfn.XLOOKUP(A28,SKUList,SKU_Data!$E$5:$E$154) -> 26437.73 | D28: =_xlfn.RANK.EQ(C28,$C$5:$C$154) -> 24 | E28: =SUMIFS($C$5:$C$154,$C$5:$C$154,">="&C28)/SUM($C$5:$C$154) -> 0.36255717 | F28: =IF(E28<=A_Limit,"A",IF(E28<=B_Limit,"B","C")) -> A | G28: =AVERAGE(_xlfn.XLOOKUP(A28,DemandCodes,DemandLast52)) -> 252.19231 | H28: =_xlfn.STDEV.S(_xlfn.XLOOKUP(A28,DemandCodes,DemandLast52)) -> 147.08008 | I28: =H28/G28 -> 0.58320606 | J28: =IF(I28<=X_Limit,"X",IF(I28<=Y_Limit,"Y","Z")) -> X | K28: =F28&J28 -> AX | L28: =AVERAGE(_xlfn.XLOOKUP(A28,DemandCodes,DemandPeak2010))/AVERAGE(_xlfn.XLOOKUP(A28,DemandCodes,DemandTrain)) -> 1.4668478 | M28: =IF(L28>=SeasonalLimit,"Yes","No") -> Yes | N28: =_xlfn.XLOOKUP(A28,SKUList,SKU_Data!$C$5:$C$154)/_xlfn.XLOOKUP(A28,SKUList,SKU_Data!$D$5:$D$154) -> 2.0118308 | O28: =IF(K28=_xlfn.XLOOKUP(A28,SKUList,SKU_Data!$F$5:$F$154),"✓","≠") -> ✓
A29: =SKU_Data!A29 -> 22629 | B29: =_xlfn.XLOOKUP(A29,SKUList,SKU_Data!$B$5:$B$154) -> SPACEBOY LUNCH BOX | C29: =_xlfn.XLOOKUP(A29,SKUList,SKU_Data!$E$5:$E$154) -> 25292.45 | D29: =_xlfn.RANK.EQ(C29,$C$5:$C$154) -> 25 | E29: =SUMIFS($C$5:$C$154,$C$5:$C$154,">="&C29)/SUM($C$5:$C$154) -> 0.37045983 | F29: =IF(E29<=A_Limit,"A",IF(E29<=B_Limit,"B","C")) -> A | G29: =AVERAGE(_xlfn.XLOOKUP(A29,DemandCodes,DemandLast52)) -> 270.01923 | H29: =_xlfn.STDEV.S(_xlfn.XLOOKUP(A29,DemandCodes,DemandLast52)) -> 180.60079 | I29: =H29/G29 -> 0.66884419 | J29: =IF(I29<=X_Limit,"X",IF(I29<=Y_Limit,"Y","Z")) -> X | K29: =F29&J29 -> AX | L29: =AVERAGE(_xlfn.XLOOKUP(A29,DemandCodes,DemandPeak2010))/AVERAGE(_xlfn.XLOOKUP(A29,DemandCodes,DemandTrain)) -> 1.7959148 | M29: =IF(L29>=SeasonalLimit,"Yes","No") -> Yes | N29: =_xlfn.XLOOKUP(A29,SKUList,SKU_Data!$C$5:$C$154)/_xlfn.XLOOKUP(A29,SKUList,SKU_Data!$D$5:$D$154) -> 1.8010039 | O29: =IF(K29=_xlfn.XLOOKUP(A29,SKUList,SKU_Data!$F$5:$F$154),"✓","≠") -> ✓
A30: =SKU_Data!A30 -> 22457 | B30: =_xlfn.XLOOKUP(A30,SKUList,SKU_Data!$B$5:$B$154) -> NATURAL SLATE HEART CHALKBOARD | C30: =_xlfn.XLOOKUP(A30,SKUList,SKU_Data!$E$5:$E$154) -> 25172.56 | D30: =_xlfn.RANK.EQ(C30,$C$5:$C$154) -> 26 | E30: =SUMIFS($C$5:$C$154,$C$5:$C$154,">="&C30)/SUM($C$5:$C$154) -> 0.37832503 | F30: =IF(E30<=A_Limit,"A",IF(E30<=B_Limit,"B","C")) -> A | G30: =AVERAGE(_xlfn.XLOOKUP(A30,DemandCodes,DemandLast52)) -> 156.69231 | H30: =_xlfn.STDEV.S(_xlfn.XLOOKUP(A30,DemandCodes,DemandLast52)) -> 69.601819 | I30: =H30/G30 -> 0.44419423 | J30: =IF(I30<=X_Limit,"X",IF(I30<=Y_Limit,"Y","Z")) -> X | K30: =F30&J30 -> AX | L30: =AVERAGE(_xlfn.XLOOKUP(A30,DemandCodes,DemandPeak2010))/AVERAGE(_xlfn.XLOOKUP(A30,DemandCodes,DemandTrain)) -> 1.6347442 | M30: =IF(L30>=SeasonalLimit,"Yes","No") -> Yes | N30: =_xlfn.XLOOKUP(A30,SKUList,SKU_Data!$C$5:$C$154)/_xlfn.XLOOKUP(A30,SKUList,SKU_Data!$D$5:$D$154) -> 3.088451 | O30: =IF(K30=_xlfn.XLOOKUP(A30,SKUList,SKU_Data!$F$5:$F$154),"✓","≠") -> ✓
A31: =SKU_Data!A31 -> 21915 | B31: =_xlfn.XLOOKUP(A31,SKUList,SKU_Data!$B$5:$B$154) -> RED HARMONICA IN BOX | C31: =_xlfn.XLOOKUP(A31,SKUList,SKU_Data!$E$5:$E$154) -> 25165.67 | D31: =_xlfn.RANK.EQ(C31,$C$5:$C$154) -> 27 | E31: =SUMIFS($C$5:$C$154,$C$5:$C$154,">="&C31)/SUM($C$5:$C$154) -> 0.38618808 | F31: =IF(E31<=A_Limit,"A",IF(E31<=B_Limit,"B","C")) -> A | G31: =AVERAGE(_xlfn.XLOOKUP(A31,DemandCodes,DemandLast52)) -> 400.5 | H31: =_xlfn.STDEV.S(_xlfn.XLOOKUP(A31,DemandCodes,DemandLast52)) -> 512.11807 | I31: =H31/G31 -> 1.2786968 | J31: =IF(I31<=X_Limit,"X",IF(I31<=Y_Limit,"Y","Z")) -> Z | K31: =F31&J31 -> AZ | L31: =AVERAGE(_xlfn.XLOOKUP(A31,DemandCodes,DemandPeak2010))/AVERAGE(_xlfn.XLOOKUP(A31,DemandCodes,DemandTrain)) -> 2.1347613 | M31: =IF(L31>=SeasonalLimit,"Yes","No") -> Yes | N31: =_xlfn.XLOOKUP(A31,SKUList,SKU_Data!$C$5:$C$154)/_xlfn.XLOOKUP(A31,SKUList,SKU_Data!$D$5:$D$154) -> 1.208511 | O31: =IF(K31=_xlfn.XLOOKUP(A31,SKUList,SKU_Data!$F$5:$F$154),"✓","≠") -> ✓
A32: =SKU_Data!A32 -> 48138 | B32: =_xlfn.XLOOKUP(A32,SKUList,SKU_Data!$B$5:$B$154) -> DOORMAT UNION FLAG | C32: =_xlfn.XLOOKUP(A32,SKUList,SKU_Data!$E$5:$E$154) -> 24942.07 | D32: =_xlfn.RANK.EQ(C32,$C$5:$C$154) -> 28 | E32: =SUMIFS($C$5:$C$154,$C$5:$C$154,">="&C32)/SUM($C$5:$C$154) -> 0.39398127 | F32: =IF(E32<=A_Limit,"A",IF(E32<=B_Limit,"B","C")) -> A | G32: =AVERAGE(_xlfn.XLOOKUP(A32,DemandCodes,DemandLast52)) -> 70.942308 | H32: =_xlfn.STDEV.S(_xlfn.XLOOKUP(A32,DemandCodes,DemandLast52)) -> 100.92191 | I32: =H32/G32 -> 1.4225913 | J32: =IF(I32<=X_Limit,"X",IF(I32<=Y_Limit,"Y","Z")) -> Z | K32: =F32&J32 -> AZ | L32: =AVERAGE(_xlfn.XLOOKUP(A32,DemandCodes,DemandPeak2010))/AVERAGE(_xlfn.XLOOKUP(A32,DemandCodes,DemandTrain)) -> 0.95941503 | M32: =IF(L32>=SeasonalLimit,"Yes","No") -> No | N32: =_xlfn.XLOOKUP(A32,SKUList,SKU_Data!$C$5:$C$154)/_xlfn.XLOOKUP(A32,SKUList,SKU_Data!$D$5:$D$154) -> 6.7638337 | O32: =IF(K32=_xlfn.XLOOKUP(A32,SKUList,SKU_Data!$F$5:$F$154),"✓","≠") -> ✓
A33: =SKU_Data!A33 -> 84946 | B33: =_xlfn.XLOOKUP(A33,SKUList,SKU_Data!$B$5:$B$154) -> ANTIQUE SILVER TEA GLASS ETCHED | C33: =_xlfn.XLOOKUP(A33,SKUList,SKU_Data!$E$5:$E$154) -> 24434.12 | D33: =_xlfn.RANK.EQ(C33,$C$5:$C$154) -> 29 | E33: =SUMIFS($C$5:$C$154,$C$5:$C$154,">="&C33)/SUM($C$5:$C$154) -> 0.40161574 | F33: =IF(E33<=A_Limit,"A",IF(E33<=B_Limit,"B","C")) -> A | G33: =AVERAGE(_xlfn.XLOOKUP(A33,DemandCodes,DemandLast52)) -> 348.84615 | H33: =_xlfn.STDEV.S(_xlfn.XLOOKUP(A33,DemandCodes,DemandLast52)) -> 224.27612 | I33: =H33/G33 -> 0.6429084 | J33: =IF(I33<=X_Limit,"X",IF(I33<=Y_Limit,"Y","Z")) -> X | K33: =F33&J33 -> AX | L33: =AVERAGE(_xlfn.XLOOKUP(A33,DemandCodes,DemandPeak2010))/AVERAGE(_xlfn.XLOOKUP(A33,DemandCodes,DemandTrain)) -> 1.8302841 | M33: =IF(L33>=SeasonalLimit,"Yes","No") -> Yes | N33: =_xlfn.XLOOKUP(A33,SKUList,SKU_Data!$C$5:$C$154)/_xlfn.XLOOKUP(A33,SKUList,SKU_Data!$D$5:$D$154) -> 1.3428289 | O33: =IF(K33=_xlfn.XLOOKUP(A33,SKUList,SKU_Data!$F$5:$F$154),"✓","≠") -> ✓
A34: =SKU_Data!A34 -> 22326 | B34: =_xlfn.XLOOKUP(A34,SKUList,SKU_Data!$B$5:$B$154) -> ROUND SNACK BOXES SET OF4 WOODLAND | C34: =_xlfn.XLOOKUP(A34,SKUList,SKU_Data!$E$5:$E$154) -> 24126.93 | D34: =_xlfn.RANK.EQ(C34,$C$5:$C$154) -> 30 | E34: =SUMIFS($C$5:$C$154,$C$5:$C$154,">="&C34)/SUM($C$5:$C$154) -> 0.40915424 | F34: =IF(E34<=A_Limit,"A",IF(E34<=B_Limit,"B","C")) -> A | G34: =AVERAGE(_xlfn.XLOOKUP(A34,DemandCodes,DemandLast52)) -> 163.40385 | H34: =_xlfn.STDEV.S(_xlfn.XLOOKUP(A34,DemandCodes,DemandLast52)) -> 118.87747 | I34: =H34/G34 -> 0.72750718 | J34: =IF(I34<=X_Limit,"X",IF(I34<=Y_Limit,"Y","Z")) -> X | K34: =F34&J34 -> AX | L34: =AVERAGE(_xlfn.XLOOKUP(A34,DemandCodes,DemandPeak2010))/AVERAGE(_xlfn.XLOOKUP(A34,DemandCodes,DemandTrain)) -> 1.1692199 | M34: =IF(L34>=SeasonalLimit,"Yes","No") -> No | N34: =_xlfn.XLOOKUP(A34,SKUList,SKU_Data!$C$5:$C$154)/_xlfn.XLOOKUP(A34,SKUList,SKU_Data!$D$5:$D$154) -> 2.8399566 | O34: =IF(K34=_xlfn.XLOOKUP(A34,SKUList,SKU_Data!$F$5:$F$154),"✓","≠") -> ✓
... A154: =SKU_Data!A154 -> 21791 | B154: =_xlfn.XLOOKUP(A154,SKUList,SKU_Data!$B$5:$B$154) -> VINTAGE HEADS AND TAILS CARD GAME | C154: =_xlfn.XLOOKUP(A154,SKUList,SKU_Data!$E$5:$E$154) -> 9984.99 | D154: =_xlfn.RANK.EQ(C154,$C$5:$C$154) -> 150 | E154: =SUMIFS($C$5:$C$154,$C$5:$C$154,">="&C154)/SUM($C$5:$C$154) -> 1 | F154: =IF(E154<=A_Limit,"A",IF(E154<=B_Limit,"B","C")) -> C | G154: =AVERAGE(_xlfn.XLOOKUP(A154,DemandCodes,DemandLast52)) -> 143.75 | H154: =_xlfn.STDEV.S(_xlfn.XLOOKUP(A154,DemandCodes,DemandLast52)) -> 160.7869 | I154: =H154/G154 -> 1.1185175 | J154: =IF(I154<=X_Limit,"X",IF(I154<=Y_Limit,"Y","Z")) -> Y | K154: =F154&J154 -> CY | L154: =AVERAGE(_xlfn.XLOOKUP(A154,DemandCodes,DemandPeak2010))/AVERAGE(_xlfn.XLOOKUP(A154,DemandCodes,DemandTrain)) -> 2.3637194 | M154: =IF(L154>=SeasonalLimit,"Yes","No") -> Yes | N154: =_xlfn.XLOOKUP(A154,SKUList,SKU_Data!$C$5:$C$154)/_xlfn.XLOOKUP(A154,SKUList,SKU_Data!$D$5:$D$154) -> 1.3353735 | O154: =IF(K154=_xlfn.XLOOKUP(A154,SKUList,SKU_Data!$F$5:$F$154),"✓","≠") -> ✓

Sheet Forecast
A1: Forecast one SKU: four methods, backtest and accuracy
A2: Pick a stock code in C4. Train = weeks 1-91 (fit), Test = weeks 92-103 (Sep-Nov 2011, the backtest), Future = weeks 104-115.
B4: Stock code (pick one) | C4: 85123A | D4: =C4&"" -> 85123A | E4: Moving-average window (weeks) | G4: 8 | K4: Backtest accuracy (test weeks 92-103) | S4: How the columns work
B5: Description | C5: =_xlfn.XLOOKUP($D$4,SKUList,SKU_Data!$B$5:$B$154) -> WHITE HANGING HEART T-LIGHT HOLDER | E5: SES α (fitted) | G5: =_xlfn.XLOOKUP($D$4,ParamCodes,Model_Params!$B$5:$B$154) -> 0.5 | K5: Method | L5: WAPE | M5: MAPE | N5: Bias | O5: Score | Q5: Check | S5: SES level: level = α × actual + (1 − α) × last level. The forecast is the last level, flat for every future week.
B6: ABC-XYZ class | C6: =_xlfn.XLOOKUP($D$4,ClsCode,ClsClass) -> AY | E6: SES α override (optional) | K6: Naive | L6: =SUM(Q106:Q117)/SUM($D$106:$D$117) -> 0.52857143 | M6: =IFERROR(AVERAGE(W106:W117),"n/a") -> 0.50439448 | N6: =(SUM(G106:G117)-SUM($D$106:$D$117))/SUM($D$106:$D$117) -> -0.43631961 | O6: =L6+ABS(N6) -> 0.96489104 | Q6: =IF(ABS(SUM(Q106:Q117)-SUMIFS(BtAbsErr,BtCode,$D$4,BtMethod,"Naive"))<0.01,"✓ same","differs") -> ✓ same | S6: Naive: the last actual (week 91 for the backtest, week 103 for the future). Moving average: average of the last N weeks.
B7: Seasonal? (Christmas uplift) | C7: =_xlfn.XLOOKUP($D$4,ClsCode,ClsSeasonal)&" ("&TEXT(_xlfn.XLOOKUP($D$4,ClsCode,ABC_XYZ!$L$5:$L$154),"0.00")&")" -> Yes (1.35) | E7: SES α used | G7: =IF(G6="",G5,G6) -> 0.5 | K7: Moving average | L7: =SUM(R106:R117)/SUM($D$106:$D$117) -> 0.44576271 | M7: =IFERROR(AVERAGE(X106:X117),"n/a") -> 0.64512202 | N7: =(SUM(H106:H117)-SUM($D$106:$D$117))/SUM($D$106:$D$117) -> -0.080205811 | O7: =L7+ABS(N7) -> 0.52596852 | Q7: =IF(ABS(SUM(R106:R117)-SUMIFS(BtAbsErr,BtCode,$D$4,BtMethod,"Moving average"))<0.01,"✓ same","differs") -> ✓ same | S7: Holt-Winters start: level = average of weeks 1-52, trend = 0, season = 9-week centred average − level (smooths out noise).
B8: Method chosen for its class | C8: =IF(AND(_xlfn.XLOOKUP(C6,BestClass,BestMethod)="Holt-Winters",_xlfn.XLOOKUP($D$4,ClsCode,ClsSeasonal)="No"),_xlfn.XLOOKUP(C6,BestClass,BestFlat),_xlfn.XLOOKUP(C6,BestClass,BestMethod)) -> Holt-Winters | E8: Holt-Winters α / β / γ | G8: =_xlfn.XLOOKUP($D$4,ParamCodes,Model_Params!$C$5:$C$154) -> 0.05 | H8: =_xlfn.XLOOKUP($D$4,ParamCodes,Model_Params!$D$5:$D$154) -> 0.05 | I8: =_xlfn.XLOOKUP($D$4,ParamCodes,Model_Params!$E$5:$E$154) -> 0 | K8: SES | L8: =SUM(S106:S117)/SUM($D$106:$D$117) -> 0.47060034 | M8: =IFERROR(AVERAGE(Y106:Y117),"n/a") -> 0.52951457 | N8: =(SUM(F106:F117)-SUM($D$106:$D$117))/SUM($D$106:$D$117) -> -0.28607178 | O8: =L8+ABS(N8) -> 0.75667212 | Q8: =IF(ABS(SUM(S106:S117)-SUMIFS(BtAbsErr,BtCode,$D$4,BtMethod,"SES"))<0.01,"✓ same","differs") -> ✓ same | S8: Then each week: level = α(actual − season a year ago) + (1−α)(last level + last trend); trend = β(level change) + (1−β)last trend;
K9: Holt-Winters | L9: =SUM(T106:T117)/SUM($D$106:$D$117) -> 0.42734709 | M9: =IFERROR(AVERAGE(Z106:Z117),"n/a") -> 0.53092891 | N9: =(SUM(M106:M117)-SUM($D$106:$D$117))/SUM($D$106:$D$117) -> -0.17466733 | O9: =L9+ABS(N9) -> 0.60201442 | Q9: =IF(ABS(SUM(T106:T117)-SUMIFS(BtAbsErr,BtCode,$D$4,BtMethod,"Holt-Winters"))<0.01,"✓ same","differs") -> ✓ same | S9: season = γ(actual − level) + (1−γ)(season a year ago). Forecast = level + trend × weeks ahead + season a year ago (never below 0).
K10: Excel FORECAST.ETS | L10: =SUM(U106:U117)/SUM($D$106:$D$117) -> 0.48165305 | M10: =IFERROR(AVERAGE(AA106:AA117),"n/a") -> 0.54911294 | N10: =(SUM(N106:N117)-SUM($D$106:$D$117))/SUM($D$106:$D$117) -> -0.024594272 | O10: =L10+ABS(N10) -> 0.50624733 | Q10: (Excel's own) | S10: Excel FORECAST.ETS: Excel's built-in Holt-Winters (AAA) with seasonality 52; it picks its own parameters, so it differs a little.
B11: The window and α override only change this sheet (the Backtest and Policy sheets use the fitted values and an 8-week window). | S11: #N/A cells are on purpose (no forecast in training weeks / no actuals in future weeks): charts skip #N/A instead of drawing zeros.
K12: Matches the Python batch run? (needs window 8 and fitted α)
A14: Wk | B14: Week starting | C14: Period | D14: Actual demand | E14: SES level | F14: SES forecast | G14: Naive forecast | H14: Moving avg forecast | I14: HW smoothed (yr 1) | J14: HW level | K14: HW trend | L14: HW season | M14: Holt-Winters forecast | N14: Excel FORECAST.ETS | Q14: |err| Naive | R14: |err| MA | S14: |err| SES | T14: |err| HW | U14: |err| ETS | V14: APE Naive | W14: APE MA | X14: APE SES | Y14: APE HW | Z14: APE ETS
A15: 1 | B15: =Demand!C$4 -> 40154 | C15: Train | D15: =INDEX(DemandAll,MATCH($D$4,DemandCodes,0),A15) -> 3138 | E15: =D15 -> 3138 | F15: =NA() -> #N/A | G15: =NA() -> #N/A | H15: =NA() -> #N/A | I15: =AVERAGE(INDEX($D$15:$D$105,MAX(1,A15-4)):INDEX($D$15:$D$105,MIN(91,A15+4))) -> 1263.2 | L15: =I15-$J$66 -> 206.79615 | M15: =NA() -> #N/A | N15: =NA() -> #N/A
A16: 2 | B16: =Demand!D$4 -> 40161 | C16: Train | D16: =INDEX(DemandAll,MATCH($D$4,DemandCodes,0),A16) -> 1286 | E16: =$G$7*D16+(1-$G$7)*E15 -> 2212 | F16: =NA() -> #N/A | G16: =NA() -> #N/A | H16: =NA() -> #N/A | I16: =AVERAGE(INDEX($D$15:$D$105,MAX(1,A16-4)):INDEX($D$15:$D$105,MIN(91,A16+4))) -> 1205.5 | L16: =I16-$J$66 -> 149.09615 | M16: =NA() -> #N/A | N16: =NA() -> #N/A
A17: 3 | B17: =Demand!E$4 -> 40168 | C17: Train | D17: =INDEX(DemandAll,MATCH($D$4,DemandCodes,0),A17) -> 125 | E17: =$G$7*D17+(1-$G$7)*E16 -> 1168.5 | F17: =NA() -> #N/A | G17: =NA() -> #N/A | H17: =NA() -> #N/A | I17: =AVERAGE(INDEX($D$15:$D$105,MAX(1,A17-4)):INDEX($D$15:$D$105,MIN(91,A17+4))) -> 1234 | L17: =I17-$J$66 -> 177.59615 | M17: =NA() -> #N/A | N17: =NA() -> #N/A
A18: 4 | B18: =Demand!F$4 -> 40175 | C18: Train | D18: =INDEX(DemandAll,MATCH($D$4,DemandCodes,0),A18) -> 0 | E18: =$G$7*D18+(1-$G$7)*E17 -> 584.25 | F18: =NA() -> #N/A | G18: =NA() -> #N/A | H18: =NA() -> #N/A | I18: =AVERAGE(INDEX($D$15:$D$105,MAX(1,A18-4)):INDEX($D$15:$D$105,MIN(91,A18+4))) -> 1251.375 | L18: =I18-$J$66 -> 194.97115 | M18: =NA() -> #N/A | N18: =NA() -> #N/A
A19: 5 | B19: =Demand!G$4 -> 40182 | C19: Train | D19: =INDEX(DemandAll,MATCH($D$4,DemandCodes,0),A19) -> 1767 | E19: =$G$7*D19+(1-$G$7)*E18 -> 1175.625 | F19: =NA() -> #N/A | G19: =NA() -> #N/A | H19: =NA() -> #N/A | I19: =AVERAGE(INDEX($D$15:$D$105,MAX(1,A19-4)):INDEX($D$15:$D$105,MIN(91,A19+4))) -> 1193 | L19: =I19-$J$66 -> 136.59615 | M19: =NA() -> #N/A | N19: =NA() -> #N/A
A20: 6 | B20: =Demand!H$4 -> 40189 | C20: Train | D20: =INDEX(DemandAll,MATCH($D$4,DemandCodes,0),A20) -> 917 | E20: =$G$7*D20+(1-$G$7)*E19 -> 1046.3125 | F20: =NA() -> #N/A | G20: =NA() -> #N/A | H20: =NA() -> #N/A | I20: =AVERAGE(INDEX($D$15:$D$105,MAX(1,A20-4)):INDEX($D$15:$D$105,MIN(91,A20+4))) -> 908.33333 | L20: =I20-$J$66 -> -148.07051 | M20: =NA() -> #N/A | N20: =NA() -> #N/A
A21: 7 | B21: =Demand!I$4 -> 40196 | C21: Train | D21: =INDEX(DemandAll,MATCH($D$4,DemandCodes,0),A21) -> 1405 | E21: =$G$7*D21+(1-$G$7)*E20 -> 1225.6562 | F21: =NA() -> #N/A | G21: =NA() -> #N/A | H21: =NA() -> #N/A | I21: =AVERAGE(INDEX($D$15:$D$105,MAX(1,A21-4)):INDEX($D$15:$D$105,MIN(91,A21+4))) -> 839.55556 | L21: =I21-$J$66 -> -216.84829 | M21: =NA() -> #N/A | N21: =NA() -> #N/A
A22: 8 | B22: =Demand!J$4 -> 40203 | C22: Train | D22: =INDEX(DemandAll,MATCH($D$4,DemandCodes,0),A22) -> 1373 | E22: =$G$7*D22+(1-$G$7)*E21 -> 1299.3281 | F22: =NA() -> #N/A | G22: =NA() -> #N/A | H22: =NA() -> #N/A | I22: =AVERAGE(INDEX($D$15:$D$105,MAX(1,A22-4)):INDEX($D$15:$D$105,MIN(91,A22+4))) -> 928.11111 | L22: =I22-$J$66 -> -128.29274 | M22: =NA() -> #N/A | N22: =NA() -> #N/A
A23: 9 | B23: =Demand!K$4 -> 40210 | C23: Train | D23: =INDEX(DemandAll,MATCH($D$4,DemandCodes,0),A23) -> 726 | E23: =$G$7*D23+(1-$G$7)*E22 -> 1012.6641 | F23: =NA() -> #N/A | G23: =NA() -> #N/A | H23: =NA() -> #N/A | I23: =AVERAGE(INDEX($D$15:$D$105,MAX(1,A23-4)):INDEX($D$15:$D$105,MIN(91,A23+4))) -> 1021.1111 | L23: =I23-$J$66 -> -35.292735 | M23: =NA() -> #N/A | N23: =NA() -> #N/A
A24: 10 | B24: =Demand!L$4 -> 40217 | C24: Train | D24: =INDEX(DemandAll,MATCH($D$4,DemandCodes,0),A24) -> 576 | E24: =$G$7*D24+(1-$G$7)*E23 -> 794.33203 | F24: =NA() -> #N/A | G24: =NA() -> #N/A | H24: =NA() -> #N/A | I24: =AVERAGE(INDEX($D$15:$D$105,MAX(1,A24-4)):INDEX($D$15:$D$105,MIN(91,A24+4))) -> 917.33333 | L24: =I24-$J$66 -> -139.07051 | M24: =NA() -> #N/A | N24: =NA() -> #N/A
A25: 11 | B25: =Demand!M$4 -> 40224 | C25: Train | D25: =INDEX(DemandAll,MATCH($D$4,DemandCodes,0),A25) -> 667 | E25: =$G$7*D25+(1-$G$7)*E24 -> 730.66602 | F25: =NA() -> #N/A | G25: =NA() -> #N/A | H25: =NA() -> #N/A | I25: =AVERAGE(INDEX($D$15:$D$105,MAX(1,A25-4)):INDEX($D$15:$D$105,MIN(91,A25+4))) -> 980 | L25: =I25-$J$66 -> -76.403846 | M25: =NA() -> #N/A | N25: =NA() -> #N/A
